Workbook
Name Valores: #REF!
Name Valores: #REF!
Name Valores: #REF!

Sheet CAPTURA
D8: FECHA | E8: =TODAY() -> 46079
D9: CLIENTE
A11: P E R S O N A F I S I C A | D11: Nombre (s): | E11: AMIRA IRACEMA | G11: ASESOR | H11: Nombre (s): | I11: MARIA ELENA | L11: LOS CAMPOS EN COLOR GRIS SON MEDIANTE SELECCION, ABRIR CATALOGO CON LA FLECHA
D12: Apellido Paterno: | E12: TORRES | H12: Apellido Paterno: | I12: HINOJOSA
D13: Apellido Materno: | E13: GONZALEZ | H13: Apellido Materno: | I13: PLANCARTE
D14: Fecha de Nacimiento: | E14: 25971 | H14: Tipo: | I14: INTERNO
D15: Nacionalidad: | E15: MEXICANA
D16: RFC: | E16: TOGA710207HC3
D17: CURP: | E17: TOOGA710207MCLRNM09 | G17: L O T E | H17: Fraccionamiento | I17: SANTTE RESIDENCIAL
D18: Lugar de Nacimiento: | E18: PIEDRAS NEGRAS, COAHUILA | H18: Prototipo: | I18: TERRENO
D19: País de Nacimiento | E19: MEXICANA | H19: Manzana: | I19: 45
D20: Estado Civil: | E20: CASADO (A) | H20: Lote: | I20: 16
D21: Régimen Conyugal: | E21: SEPARACION DE BIENES | H21: Número oficial: | I21: 114
D22: Ocupación: | E22: FINANCIERA | H22: Calle: | I22: AZALEA
D23: Domicilio - Calle: | E23: CALLE VENEDELLO | H23: Exp. Catastral:
D24: Número Ext. / Int | E24: 1612 | H24: Superficie: | I24: 166.929
D25: Colonia: | E25: VILLAS CANTERIAS | H25: Precio M2: | I25: =I26/I24 -> 12580.199
D26: Ciudad/Municipio: | E26: MONTERREY | H26: Precio: | I26: 2100000
D27: Estado: | E27: NUEVO LEÓN | L27: CAMPOS A CAPTURAR
D28: Código Postal: | E28: 64989 | G28: F O R M A D E P A G O | H28: Forma de pago: | I28: CREDITO DIRECTO
D29: Teléfono Casa: | E29: - | H29: Inst. Crédito: | I29: N/A
D30: Teléfono Celular: | E30: 81 1753 3008 | H30: Tasa interés: | I30: 0
D31: Teléfono Oficina: | E31: - | H31: ID | I31: CONCEPTO | J31: FECHA | K31: CAPITAL | L31: INTERES | M31: PAGO CAPITAL | N31: PAGO TOTAL
D32: E-mail: | E32: amira_torres@hotmail.com | H32: 1 | I32: SEPARACION | J32: 14 ENERO 2026 | K32: =(I26) -> 2100000 | L32: =((K32*I$30)/365)*30.4 -> 0 | M32: 50000 | N32: =(M32) -> 50000
H33: 2 | I33: ENGANCHE | J33: 26 ENERO 2026 | K33: =(K32-M32) -> 2050000 | L33: =((K33*I$30)/365)*30.4 -> 0 | M33: 630000 | N33: =(L33+M33) -> 630000
A34: P E R S O N A M O R A L | C34: E M P R E S A | D34: Empresa: | H34: 3 | I34: ESCRITURACIÓN | J34: 2 MARZO 2026 | K34: =(K33-M33) -> 1420000 | L34: =((K34*I$30)/365)*30.4 -> 0 | M34: =I26-M32-M33 -> 1420000 | N34: =(L34+M34) -> 1420000
D35: RFC:
D36: Domicilio - Calle:
D37: Número Ext. / Int
D38: Colonia:
D39: Ciudad/Municipio:
D40: Estado:
D41: Código Postal:
D42: Teléfono Oficina:
C44: R E P R E S E N T A N T E L E G A L | D44: Nombre (s):
D47: Apellido Paterno:
D48: Apellido Materno: | I48: VALOR TOTAL: | L48: =SUM(L32:L47) -> 0 | M48: =SUM(M32:M47) -> 2100000 | N48: =SUM(N32:N47) -> 2100000
D49: Fecha de Nacimiento:
D50: Nacionalidad: | G50: O B S E R V A C I O N E S | H50: FECHA FIRMA DE CONTRATO: | J50: 45944
D51: RFC:
...

Sheet CheckList
N2: San Pedro Garza García, Nuevo León
N3: Fecha: | O3: =(CAPTURA!E8) -> 46079
N4: Num. Cliente: | O4: =(CAPTURA!E9) -> 0
B7: CHECK LIST (ALT.000)
B10: NOMBRE CLIENTE: | D10: =CONCATENATE(CAPTURA!E11, " ",CAPTURA!E12, " ", CAPTURA!E13) -> AMIRA IRACEMA TORRES GONZALEZ
B12: TIPO DE CREDITO: | D12: =(CAPTURA!I28) -> CREDITO DIRECTO | L12: INSTITUCION: | M12: =(CAPTURA!I29) -> N/A
B16: DESARROLLO: | D16: =(CAPTURA!I17) -> SANTTE RESIDENCIAL | L16: PROTOTIPO: | M16: =(CAPTURA!I18) -> TERRENO
B19: UBICACION:
D20: MANZANA | F20: LOTE | H20: NUM. OFICIAL | L20: VALOR DE LA OPERACION
D21: =(CAPTURA!I19) -> 45 | F21: =(CAPTURA!I20) -> 16 | H21: =(CAPTURA!I21) -> 114 | L21: =(CAPTURA!I26) -> 2100000
B26: PERSONA FISICA | C26: A | D26: DOCUMENTOS SOLICITADOS | M26: B | N26: OBSERVACIONES
D27: ACTAS DE NAC., MATRIMONIO EN SU CASO
D28: IDENTIFICACION OFICIAL -INE,S
D29: CURPS
D30: COMPROBANTE DE DOMICILIO
D31: CONSTANCIA DE RFC O CEDULA FISCAL
D32: CORREO ELECTRONICO
D33: TELEFONO CELULAR
B35: PERSONA MORAL | C35: A | D35: DOCUMENTOS SOLICITADOS | M35: B | N35: OBSERVACIONES
D36: ACTA CONSTITUTIVA /REVISAR BOLETA DE INSCRIPCION AL RPP Y PODER
D37: CEDULA FISCAL
D38: COMPROBANTE DE DOMICILIO
D39: TELEFONO
D40: CORREO ELECTRONICO
D41: DOMICILIO Y GIRO DE LA EMPRESA
C43: REPRESENTANTE LEGAL
D44: PODER NOTARIAL
D45: IDENTIFICACION OFICIAL -INE,S
D46: CEDULA FISCAL
D47: CORREO ELECTRONICO Y TEL
D48: COMPROBANTE DE DOMICILIO DEL REPRESENTANTE LEGAL
B50: EXPEDIENTE INTERRA | C50: A | D50: DOCUMENTOS SOLICITADOS | M50: B | N50: OBSERVACIONES
D51: HOJA DE GENERALES
D52: OFERTA DE COMPRA
D53: CONTRATO DE UBICACIÓN
D54: PLANO MANZANERO
B56: NOMENCLATURA:
C57: A | D57: VALIDACION DE ENTREGA DE DOCUMENTOS (VENTAS)
C58: B | D58: VALIDACION DE RECEPCION DE DOCUMENTOS (TITULACION-DICTAMEN)
B61: OBSERVACIONES
...

Sheet Ubicacion
B7: CONTRATO DE UBICACIÓN
B12: CONTRATO DE UBICACIÓN DE LOTE DE LA EMPRESA VINTAGO DESARROLLOS, SA DE CV
B14: PARQUE IBP SALINAS
B16: UBICADO EN:
B18: SALINAS VICTORIA, NUEVO LEON
Q23: COSTO DE LA TERRENO | S23: =(CAPTURA!I26) -> 2100000
C33: MANZANA | H33: LOTE | L33: CALLE | AG33: NO.
C34: =(CAPTURA!I19) -> 45 | H34: =(CAPTURA!I20) -> 16 | L34: =(CAPTURA!I22) -> AZALEA | AG34: =(CAPTURA!I21) -> 114
D45: =CONCATENATE(CAPTURA!E11, " ",CAPTURA!E12, " ", CAPTURA!E13) -> AMIRA IRACEMA TORRES GONZALEZ | V45: =CONCATENATE(CAPTURA!I11, " ",CAPTURA!I12, " ",CAPTURA!I13) -> MARIA ELENA HINOJOSA PLANCARTE
D46: NOMBRE Y FIRMA DEL CLIENTE O APODERADO | V46: NOMBRE Y FIRMA DEL ASESOR

Sheet Cancelacion
B6: CANCELACION DE UBICACIÓN
AD8: =TODAY() -> 46079
B11: SOLICITUD PARA CANCELAR UBICACIONES EN EL FRACCIONAMIENTO:
B13: =(CAPTURA!I17) -> SANTTE RESIDENCIAL
B15: UBICADO EN:
B17: SALINAS VICTORIA, NUEVO LEON
C20: NUMCTE | H20: NOMBRE DEL CLIENTE
C21: =(CAPTURA!E9) -> 0 | H21: =CONCATENATE(CAPTURA!E11, " ",CAPTURA!E12, " ", CAPTURA!E13) -> AMIRA IRACEMA TORRES GONZALEZ
C25: MANZANA | H25: LOTE | L25: CALLE | AG25: NO.
C26: =(CAPTURA!I19) -> 45 | H26: =(CAPTURA!I20) -> 16 | L26: =(CAPTURA!I22) -> AZALEA | AG26: =(CAPTURA!I21) -> 114
L28: MOTIVO
C32: PAGOS REALIZADOS | L32: 0
C33: GASTOS ADMINISTRATIVOS | L33: 0
C34: TOTAL A DEVOLVER | L34: 0
C35: OBSERVACIONES:
D48: =CONCATENATE(CAPTURA!E11, " ",CAPTURA!E12, " ", CAPTURA!E13) -> AMIRA IRACEMA TORRES GONZALEZ | V48: =CONCATENATE(CAPTURA!I11, " ",CAPTURA!I12, " ",CAPTURA!I13) -> MARIA ELENA HINOJOSA PLANCARTE
D49: NOMBRE Y FIRMA DEL CLIENTE O APODERADO | V49: NOMBRE Y FIRMA DEL ASESOR

Sheet Cotizacion
J2: San Pedro Garza García, Nuevo León
J3: Fecha: | K3: =(CAPTURA!E8) -> 46079
J4: Num. Cliente: | K4: =(CAPTURA!E9) -> 0
B7: C O T I Z A C I O N
B9: O F E R E N T E
B10: Nombre: | C10: AMIRA TORRES | H10: Teléfono Celular: | I10: =CAPTURA!E30 -> 81 1753 3008
B11: Domicilio - Calle: | C11: =CAPTURA!E23 -> CALLE VENEDELLO | H11: Teléfono Oficina: | I11: =CAPTURA!E31 -> -
B12: Número Ext. / Int. | C12: =CAPTURA!E24 -> 1612 | H12: E-mail: | I12: =CAPTURA!E32 -> amira_torres@hotmail.com
B13: Colonia: | C13: =CAPTURA!E25 -> VILLAS CANTERIAS
B14: Ciudad/Municipio: | C14: =CAPTURA!E26 -> MONTERREY | H14: Firma Contrato: | I14: =CAPTURA!J32 -> 14 ENERO 2026
B15: Estado: | C15: =CAPTURA!E27 -> NUEVO LEÓN
B17: L O T E
B18: Fraccionamiento: | C18: =(CAPTURA!I17) -> SANTTE RESIDENCIAL | H18: Superficie M2: | I18: =CAPTURA!I24 -> 166.929
B19: Manzana: | C19: =CAPTURA!I19 -> 45 | H19: Precio M2: | I19: =CAPTURA!I25 -> 12580.199
B20: Lote: | C20: =CAPTURA!I20 -> 16 | H20: Precio: | I20: =CAPTURA!I26 -> 2100000
B21: Número Oficial: | C21: =CAPTURA!I21 -> 114 | H21: Prototipo:
B22: Calle: | C22: =CAPTURA!I22 -> AZALEA
B24: F O R M A D E P A G O
B25: Tipo de Crédito: | E25: =(CAPTURA!I28) -> CREDITO DIRECTO
B26: Institución de Crédito:
B28: NUMERO | C28: CONCEPTO | E28: FECHA | F28: CAPITAL | H28: INTERES | I28: PAGO CAPITAL | K28: PAGO TOTAL
B30: =(CAPTURA!H32) -> 1 | C30: =CAPTURA!I32 -> SEPARACION | E30: =(CAPTURA!J32) -> 14 ENERO 2026 | F30: =(CAPTURA!K32) -> 2100000 | G30: =(CAPTURA!K32) -> 2100000 | H30: =(CAPTURA!L32) -> 0 | I30: =(CAPTURA!M32) -> 50000 | J30: =(CAPTURA!M32) -> 50000 | K30: =(CAPTURA!N32) -> 50000
B31: =(CAPTURA!H33) -> 2 | C31: =(CAPTURA!I33) -> ENGANCHE | E31: =(CAPTURA!J33) -> 26 ENERO 2026 | F31: =(CAPTURA!K33) -> 2050000 | G31: =(CAPTURA!K33) -> 2050000 | H31: =(CAPTURA!L33) -> 0 | I31: =(CAPTURA!M33) -> 630000 | J31: =(CAPTURA!M33) -> 630000 | K31: =(CAPTURA!N33) -> 630000
B32: =(CAPTURA!H34) -> 3 | C32: =(CAPTURA!I34) -> ESCRITURACIÓN | E32: =(CAPTURA!J34) -> 2 MARZO 2026 | F32: =(CAPTURA!K34) -> 1420000 | G32: =(CAPTURA!K34) -> 1420000 | H32: =(CAPTURA!L34) -> 0 | I32: =(CAPTURA!M34) -> 1420000 | J32: =(CAPTURA!M34) -> 1420000 | K32: =(CAPTURA!N34) -> 1420000
B33: =(CAPTURA!H35) -> 0 | C33: =(CAPTURA!I35) -> 0 | E33: =(CAPTURA!J35) -> 0 | F33: =(CAPTURA!K35) -> 0 | G33: =(CAPTURA!K35) -> 0 | H33: =(CAPTURA!L35) -> 0 | I33: =(CAPTURA!M35) -> 0 | J33: =(CAPTURA!M35) -> 0 | K33: =(CAPTURA!N35) -> 0
B34: =(CAPTURA!H36) -> 0 | C34: =(CAPTURA!I36) -> 0 | E34: =(CAPTURA!J36) -> 0 | F34: =(CAPTURA!K36) -> 0 | G34: =(CAPTURA!K36) -> 0 | H34: =(CAPTURA!L36) -> 0 | I34: =(CAPTURA!M36) -> 0 | J34: =(CAPTURA!M36) -> 0 | K34: =(CAPTURA!N36) -> 0
B35: =(CAPTURA!H37) -> 0 | C35: =(CAPTURA!I37) -> 0 | E35: =(CAPTURA!J37) -> 0 | F35: =(CAPTURA!K37) -> 0 | G35: =(CAPTURA!K37) -> 0 | H35: =(CAPTURA!L37) -> 0 | I35: =(CAPTURA!M37) -> 0 | J35: =(CAPTURA!M37) -> 0 | K35: =(CAPTURA!N37) -> 0
B36: =(CAPTURA!H38) -> 0 | C36: =(CAPTURA!I38) -> 0 | E36: =(CAPTURA!J38) -> 0 | F36: =(CAPTURA!K38) -> 0 | G36: =(CAPTURA!K38) -> 0 | H36: =(CAPTURA!L38) -> 0 | I36: =(CAPTURA!M38) -> 0 | J36: =(CAPTURA!M38) -> 0 | K36: =(CAPTURA!N38) -> 0
B37: =(CAPTURA!H39) -> 0 | C37: =(CAPTURA!I39) -> 0 | E37: =(CAPTURA!J39) -> 0 | F37: =(CAPTURA!K39) -> 0 | G37: =(CAPTURA!K39) -> 0 | H37: =(CAPTURA!L39) -> 0 | I37: =(CAPTURA!M39) -> 0 | J37: =(CAPTURA!M39) -> 0 | K37: =(CAPTURA!N39) -> 0
B38: =(CAPTURA!H40) -> 0 | C38: =(CAPTURA!I40) -> 0 | E38: =(CAPTURA!J40) -> 0 | F38: =(CAPTURA!K40) -> 0 | G38: =(CAPTURA!K40) -> 0 | H38: =(CAPTURA!L40) -> 0 | I38: =(CAPTURA!M40) -> 0 | J38: =(CAPTURA!M40) -> 0 | K38: =(CAPTURA!N40) -> 0
B39: =(CAPTURA!H41) -> 0 | C39: =(CAPTURA!I41) -> 0 | E39: =(CAPTURA!J41) -> 0 | F39: =(CAPTURA!K41) -> 0 | G39: =(CAPTURA!K41) -> 0 | H39: =(CAPTURA!L41) -> 0 | I39: =(CAPTURA!M41) -> 0 | J39: =(CAPTURA!M41) -> 0 | K39: =(CAPTURA!N41) -> 0
B40: =(CAPTURA!H42) -> 0 | C40: =(CAPTURA!I42) -> 0 | E40: =(CAPTURA!J42) -> 0 | F40: =(CAPTURA!K42) -> 0 | G40: =(CAPTURA!K42) -> 0 | H40: =(CAPTURA!L42) -> 0 | I40: =(CAPTURA!M42) -> 0 | J40: =(CAPTURA!M42) -> 0 | K40: =(CAPTURA!N42) -> 0
B41: =(CAPTURA!H44) -> 0 | C41: =(CAPTURA!I44) -> 0 | E41: =(CAPTURA!J44) -> 0 | F41: =(CAPTURA!K44) -> 0 | G41: =(CAPTURA!K43) -> 0 | H41: =(CAPTURA!L44) -> 0 | I41: =(CAPTURA!M44) -> 0 | J41: =(CAPTURA!M43) -> 0 | K41: =(CAPTURA!N44) -> 0
B42: =(CAPTURA!H45) -> 0 | C42: =(CAPTURA!I45) -> 0 | E42: =(CAPTURA!J45) -> 0 | F42: =(CAPTURA!K45) -> 0 | G42: =(CAPTURA!K44) -> 0 | H42: =(CAPTURA!L45) -> 0 | I42: =(CAPTURA!M45) -> 0 | J42: =(CAPTURA!M44) -> 0 | K42: =(CAPTURA!N45) -> 0
B43: =(CAPTURA!H46) -> 0 | C43: =(CAPTURA!I46) -> 0 | E43: =(CAPTURA!J46) -> 0 | F43: =(CAPTURA!K46) -> 0 | G43: =(CAPTURA!K45) -> 0 | H43: =(CAPTURA!L46) -> 0 | I43: =(CAPTURA!M46) -> 0 | J43: =(CAPTURA!M45) -> 0 | K43: =(CAPTURA!N46) -> 0
B44: =(CAPTURA!H47) -> 0 | C44: =(CAPTURA!I47) -> 0 | E44: =(CAPTURA!J47) -> 0 | F44: =(CAPTURA!K47) -> 0 | G44: =(CAPTURA!K46) -> 0 | H44: =(CAPTURA!L47) -> 0 | I44: =(CAPTURA!M47) -> 0 | J44: =(CAPTURA!M46) -> 0 | K44: =(CAPTURA!N47) -> 0
C46: =(CAPTURA!I48) -> VALOR TOTAL: | F46: =(CAPTURA!K48) -> 0 | G46: =(CAPTURA!K48) -> 0 | H46: =(CAPTURA!L48) -> 0 | I46: =(CAPTURA!M48) -> 2100000 | J46: =(CAPTURA!M48) -> 2100000 | K46: =(CAPTURA!N48) -> 2100000
J47: =(CAPTURA!M49) -> 0
B49: DATOS PARA DEPOSITOS | E49: CONDICIONES ESPECIALES:
B50: VINTAGO DESARROLLOS, S.A. DE C.V.
...

Sheet Oferta de compra_fisica
J2: San Pedro Garza García, Nuevo León
J3: Fecha: | K3: =(CAPTURA!E8) -> 46079
J4: Num. Cliente: | K4: =(CAPTURA!E9) -> 0
B7: O F E R T A D E C O M P R A (ALT.001)
B9: O F E R E N T E
B10: Nombre: | C10: AMIRA TORRES | H10: Teléfono Celular: | I10: =CAPTURA!E30 -> 81 1753 3008
B11: Domicilio - Calle: | C11: =CAPTURA!E23 -> CALLE VENEDELLO | H11: Teléfono Oficina: | I11: =CAPTURA!E31 -> -
B12: Número Ext. / Int. | C12: =CAPTURA!E24 -> 1612 | H12: E-mail: | I12: =CAPTURA!E32 -> amira_torres@hotmail.com
B13: Colonia: | C13: =CAPTURA!E25 -> VILLAS CANTERIAS
B14: Ciudad/Municipio: | C14: =CAPTURA!E26 -> MONTERREY | H14: Firma Contrato: | I14: =CAPTURA!J32 -> 14 ENERO 2026
B15: Estado: | C15: =CAPTURA!E27 -> NUEVO LEÓN
B17: L O T E
B18: Fraccionamiento: | C18: =(CAPTURA!I17) -> SANTTE RESIDENCIAL | H18: Superficie M2: | I18: =CAPTURA!I24 -> 166.929
B19: Manzana: | C19: =CAPTURA!I19 -> 45 | H19: Precio M2: | I19: =CAPTURA!I25 -> 12580.199
B20: Lote: | C20: =CAPTURA!I20 -> 16 | H20: Precio: | I20: =CAPTURA!I26 -> 2100000
B21: Número Oficial: | C21: =CAPTURA!I21 -> 114 | H21: Prototipo:
B22: Calle: | C22: =CAPTURA!I22 -> AZALEA
B24: F O R M A D E P A G O
B25: Tipo de Crédito: | E25: =(CAPTURA!I28) -> CREDITO DIRECTO
B26: Institución de Crédito:
B28: NUMERO | C28: CONCEPTO | E28: FECHA | F28: CAPITAL | H28: INTERES | I28: PAGO CAPITAL | K28: PAGO TOTAL
B30: =(CAPTURA!H32) -> 1 | C30: =CAPTURA!I32 -> SEPARACION | E30: =(CAPTURA!J32) -> 14 ENERO 2026 | F30: =(CAPTURA!K32) -> 2100000 | G30: =(CAPTURA!K32) -> 2100000 | H30: =(CAPTURA!L32) -> 0 | I30: =(CAPTURA!M32) -> 50000 | J30: =(CAPTURA!M32) -> 50000 | K30: =(CAPTURA!N32) -> 50000
B31: =(CAPTURA!H33) -> 2 | C31: =(CAPTURA!I33) -> ENGANCHE | E31: =(CAPTURA!J33) -> 26 ENERO 2026 | F31: =(CAPTURA!K33) -> 2050000 | G31: =(CAPTURA!K33) -> 2050000 | H31: =(CAPTURA!L33) -> 0 | I31: =(CAPTURA!M33) -> 630000 | J31: =(CAPTURA!M33) -> 630000 | K31: =(CAPTURA!N33) -> 630000
B32: =(CAPTURA!H34) -> 3 | C32: =(CAPTURA!I34) -> ESCRITURACIÓN | E32: =(CAPTURA!J34) -> 2 MARZO 2026 | F32: =(CAPTURA!K34) -> 1420000 | G32: =(CAPTURA!K34) -> 1420000 | H32: =(CAPTURA!L34) -> 0 | I32: =(CAPTURA!M34) -> 1420000 | J32: =(CAPTURA!M34) -> 1420000 | K32: =(CAPTURA!N34) -> 1420000
B33: =(CAPTURA!H35) -> 0 | C33: =(CAPTURA!I35) -> 0 | E33: =(CAPTURA!J35) -> 0 | F33: =(CAPTURA!K35) -> 0 | G33: =(CAPTURA!K35) -> 0 | H33: =(CAPTURA!L35) -> 0 | I33: =(CAPTURA!M35) -> 0 | J33: =(CAPTURA!M35) -> 0 | K33: =(CAPTURA!N35) -> 0
B34: =(CAPTURA!H36) -> 0 | C34: =(CAPTURA!I36) -> 0 | E34: =(CAPTURA!J36) -> 0 | F34: =(CAPTURA!K36) -> 0 | G34: =(CAPTURA!K36) -> 0 | H34: =(CAPTURA!L36) -> 0 | I34: =(CAPTURA!M36) -> 0 | J34: =(CAPTURA!M36) -> 0 | K34: =(CAPTURA!N36) -> 0
B35: =(CAPTURA!H37) -> 0 | C35: =(CAPTURA!I37) -> 0 | E35: =(CAPTURA!J37) -> 0 | F35: =(CAPTURA!K37) -> 0 | G35: =(CAPTURA!K37) -> 0 | H35: =(CAPTURA!L37) -> 0 | I35: =(CAPTURA!M37) -> 0 | J35: =(CAPTURA!M37) -> 0 | K35: =(CAPTURA!N37) -> 0
B36: =(CAPTURA!H38) -> 0 | C36: =(CAPTURA!I38) -> 0 | E36: =(CAPTURA!J38) -> 0 | F36: =(CAPTURA!K38) -> 0 | G36: =(CAPTURA!K38) -> 0 | H36: =(CAPTURA!L38) -> 0 | I36: =(CAPTURA!M38) -> 0 | J36: =(CAPTURA!M38) -> 0 | K36: =(CAPTURA!N38) -> 0
B37: =(CAPTURA!H39) -> 0 | C37: =(CAPTURA!I39) -> 0 | E37: =(CAPTURA!J39) -> 0 | F37: =(CAPTURA!K39) -> 0 | G37: =(CAPTURA!K39) -> 0 | H37: =(CAPTURA!L39) -> 0 | I37: =(CAPTURA!M39) -> 0 | J37: =(CAPTURA!M39) -> 0 | K37: =(CAPTURA!N39) -> 0
B38: =(CAPTURA!H40) -> 0 | C38: =(CAPTURA!I40) -> 0 | E38: =(CAPTURA!J40) -> 0 | F38: =(CAPTURA!K40) -> 0 | G38: =(CAPTURA!K40) -> 0 | H38: =(CAPTURA!L40) -> 0 | I38: =(CAPTURA!M40) -> 0 | J38: =(CAPTURA!M40) -> 0 | K38: =(CAPTURA!N40) -> 0
B39: =(CAPTURA!H41) -> 0 | C39: =(CAPTURA!I41) -> 0 | E39: =(CAPTURA!J41) -> 0 | F39: =(CAPTURA!K41) -> 0 | G39: =(CAPTURA!K41) -> 0 | H39: =(CAPTURA!L41) -> 0 | I39: =(CAPTURA!M41) -> 0 | J39: =(CAPTURA!M41) -> 0 | K39: =(CAPTURA!N41) -> 0
B40: =(CAPTURA!H42) -> 0 | C40: =(CAPTURA!I42) -> 0 | E40: =(CAPTURA!J42) -> 0 | F40: =(CAPTURA!K42) -> 0 | G40: =(CAPTURA!K42) -> 0 | H40: =(CAPTURA!L42) -> 0 | I40: =(CAPTURA!M42) -> 0 | J40: =(CAPTURA!M42) -> 0 | K40: =(CAPTURA!N42) -> 0
B41: =(CAPTURA!H44) -> 0 | C41: =(CAPTURA!I44) -> 0 | E41: =(CAPTURA!J44) -> 0 | F41: =(CAPTURA!K44) -> 0 | G41: =(CAPTURA!K43) -> 0 | H41: =(CAPTURA!L44) -> 0 | I41: =(CAPTURA!M44) -> 0 | J41: =(CAPTURA!M43) -> 0 | K41: =(CAPTURA!N44) -> 0
B42: =(CAPTURA!H45) -> 0 | C42: =(CAPTURA!I45) -> 0 | E42: =(CAPTURA!J45) -> 0 | F42: =(CAPTURA!K45) -> 0 | G42: =(CAPTURA!K44) -> 0 | H42: =(CAPTURA!L45) -> 0 | I42: =(CAPTURA!M45) -> 0 | J42: =(CAPTURA!M44) -> 0 | K42: =(CAPTURA!N45) -> 0
B43: =(CAPTURA!H46) -> 0 | C43: =(CAPTURA!I46) -> 0 | E43: =(CAPTURA!J46) -> 0 | F43: =(CAPTURA!K46) -> 0 | G43: =(CAPTURA!K45) -> 0 | H43: =(CAPTURA!L46) -> 0 | I43: =(CAPTURA!M46) -> 0 | J43: =(CAPTURA!M45) -> 0 | K43: =(CAPTURA!N46) -> 0
B44: =(CAPTURA!H47) -> 0 | C44: =(CAPTURA!I47) -> 0 | E44: =(CAPTURA!J47) -> 0 | F44: =(CAPTURA!K47) -> 0 | G44: =(CAPTURA!K46) -> 0 | H44: =(CAPTURA!L47) -> 0 | I44: =(CAPTURA!M47) -> 0 | J44: =(CAPTURA!M46) -> 0 | K44: =(CAPTURA!N47) -> 0
C46: =(CAPTURA!I48) -> VALOR TOTAL: | F46: =(CAPTURA!K48) -> 0 | G46: =(CAPTURA!K48) -> 0 | H46: =(CAPTURA!L48) -> 0 | I46: =(CAPTURA!M48) -> 2100000 | J46: =(CAPTURA!M48) -> 2100000 | K46: =(CAPTURA!N48) -> 2100000
J47: =(CAPTURA!M49) -> 0
B49: DATOS PARA DEPOSITOS | E49: CONDICIONES ESPECIALES:
B50: VINTAGO DESARROLLOS, S.A. DE C.V.
...

Sheet Generales_fisica
I2: San Pedro Garza García, Nuevo León
I3: Fecha: | J3: =(CAPTURA!E8) -> 46079
I4: Num. Cliente: | J4: =(CAPTURA!E9) -> 0
B7: D A T O S G E N E R A L E S D E L S O L I C I T A N T E (ALT.002)
B9: Nombre: | C9: YOLANDA VILLAREAL GARZA | G9: Teléfono Casa:
B10: Domicilio - Calle: | C10: =CAPTURA!E23 -> CALLE VENEDELLO | G10: Teléfono Celular: | H10: =CAPTURA!E30 -> 81 1753 3008
B11: Número Ext. / Int | C11: =CAPTURA!E24 -> 1612 | G11: Teléfono Oficina:
B12: Colonia: | C12: =CAPTURA!E25 -> VILLAS CANTERIAS | G12: E-mail: | H12: =CAPTURA!E32 -> amira_torres@hotmail.com
B13: Ciudad/Municipio: | C13: =CAPTURA!E26 -> MONTERREY
B14: Estado: | C14: =CAPTURA!E27 -> NUEVO LEÓN
B15: Código postal: | C15: =CAPTURA!E28 -> 64989 | G15: Estado Civil: | H15: =CAPTURA!E20 -> CASADO (A)
B16: RFC: | C16: =CAPTURA!E16 -> TOGA710207HC3 | G16: Régimen conyugal: | H16: =(CAPTURA!E21) -> SEPARACION DE BIENES
B17: CURP: | C17: =CAPTURA!E17 -> TOOGA710207MCLRNM09 | G17: Ocupación: | H17: =CAPTURA!E22 -> FINANCIERA
B18: Lugar de Nacimiento: | C18: =CAPTURA!E18 -> PIEDRAS NEGRAS, COAHUILA
B19: Fecha de nacimiento: | C19: =CAPTURA!E14 -> 25971
B20: Nacionalidad: | C20: =CAPTURA!E15 -> MEXICANA
B23: L O T E
B24: Fraccionamiento: | C24: =(CAPTURA!I17) -> SANTTE RESIDENCIAL | G24: Superficie M2: | H24: =CAPTURA!I24 -> 166.929
B25: Manzana: | C25: =CAPTURA!I19 -> 45 | G25: Precio M2: | H25: =CAPTURA!I25 -> 12580.199
B26: Lote: | C26: =CAPTURA!I20 -> 16 | G26: Precio: | H26: =CAPTURA!I26 -> 2100000
B27: Número Oficial: | C27: =CAPTURA!I21 -> 114 | G27: Exp. Catastral: | H27: =(CAPTURA!I23) -> 0
B28: Calle: | C28: =CAPTURA!I22 -> AZALEA | G28: Prototipo: | H28: =(CAPTURA!I18) -> TERRENO
B30: OBSERVACIONES
B50: =C9 -> YOLANDA VILLAREAL GARZA
B51: CLIENTE | I51: ASESOR

Sheet Vobocontrato_fisica
J1: CONTRATO VOBO
B6: Fecha: | C6: =(CAPTURA!E8) -> 46079 | F6: San Pedro Garza García, Nuevo León
B8: Fraccionamiento: | C8: =(CAPTURA!I17) -> SANTTE RESIDENCIAL | F8: Mza: | G8: =(CAPTURA!I19) -> 45 | H8: Lote: | I8: =(CAPTURA!I20) -> 16 | K8: Int: | L8: =(CAPTURA!I21) -> 114
B10: Comprador: | C10: =CONCATENATE(CAPTURA!E11, " ",CAPTURA!E12, " ", CAPTURA!E13) -> AMIRA IRACEMA TORRES GONZALEZ | H10: M2: | I10: =(CAPTURA!I24) -> 166.929
B12: RFC: | C12: =(CAPTURA!E16) -> TOGA710207HC3
B14: Precio: | C14: =(CAPTURA!I26) -> 2100000 | F14: Precio por M2: $ | I14: =(CAPTURA!I25) -> 12580.199
B16: Exp. Catastral: | C16: =(CAPTURA!I23) -> 0 | F16: Prototipo: | I16: =(CAPTURA!I18) -> TERRENO
B18: Plazo: | C18: CONTADO | F18: Tasa de interés: | I18: =(CAPTURA!I30) -> 0
B20: Nota:
B21: Se procederá a la firma del contrato una vez liquidado el monto del mantenimiento, en caso de cancelación la penalización será por el importe del mantenimiento.
D27: KARLA MARQUEZ | F27: ALEJANDRO REYES TELLEZ | J27: FABIAN GONZALEZ QUIROGA
D28: DIRECCION DE ADMON. Y FINANZAS | F28: VENTAS | J28: DIRECTOR GENERAL
J30: CONTRATO VOBO
B35: Fecha: | C35: =(CAPTURA!E8) -> 46079 | F35: San Pedro Garza García, Nuevo León
B37: Fraccionamiento: | C37: =(CAPTURA!I17) -> SANTTE RESIDENCIAL | F37: Mza: | G37: =(CAPTURA!I19) -> 45 | H37: Lote: | I37: =(CAPTURA!I20) -> 16 | K37: Int: | L37: =(CAPTURA!I21) -> 114
B39: Comprador: | C39: =CONCATENATE(CAPTURA!E11, " ",CAPTURA!E12, " ", CAPTURA!E13) -> AMIRA IRACEMA TORRES GONZALEZ | H39: M2: | I39: =(CAPTURA!I24) -> 166.929
B41: RFC: | C41: =(CAPTURA!E16) -> TOGA710207HC3
B43: Precio: | C43: =(CAPTURA!I26) -> 2100000 | F43: Precio por M2: $ | I43: =(CAPTURA!I25) -> 12580.199
B45: Exp. Catastral: | C45: =(CAPTURA!I23) -> 0 | F45: Prototipo: | I45: =(CAPTURA!I18) -> TERRENO
B47: Plazo: | C47: CONTADO | F47: Tasa de interés: | I47: =(CAPTURA!I30) -> 0
B49: Nota:
B50: Se procederá a la firma del contrato una vez liquidado el monto del mantenimiento, en caso de cancelación la penalización será por el importe del mantenimiento.
D56: KARLA MARQUEZ | F56: ALEJANDRO REYES TELLEZ | J56: FABIAN GONZALEZ QUIROGA
D57: DIRECCION DE ADMON. Y FINANZAS | F57: VENTAS | J57: DIRECCION GENERAL

Sheet VoboFolio_fisica
J1: FOLIO VOBO
B6: Fecha: | C6: =(CAPTURA!E8) -> 46079 | F6: San Pedro Garza García, Nuevo León
B8: Fraccionamiento: | C8: =(CAPTURA!I17) -> SANTTE RESIDENCIAL | F8: Mza: | G8: =(CAPTURA!I19) -> 45 | H8: Lote: | I8: =(CAPTURA!I20) -> 16 | K8: Int: | L8: =(CAPTURA!I21) -> 114
B10: Comprador: | C10: =CONCATENATE(CAPTURA!E11, " ",CAPTURA!E12, " ", CAPTURA!E13) -> AMIRA IRACEMA TORRES GONZALEZ | H10: M2: | I10: =(CAPTURA!I24) -> 166.929
B12: RFC: | C12: =(CAPTURA!E16) -> TOGA710207HC3
B14: Precio: | C14: =(CAPTURA!I26) -> 2100000 | F14: Precio por M2: $ | I14: =(CAPTURA!I25) -> 12580.199
B16: Exp. Catastral: | C16: =(CAPTURA!I23) -> 0 | F16: Prototipo: | I16: =(CAPTURA!I18) -> TERRENO
B18: Esc. Pública: | F18: Notaria:
B20: Nota:
D27: HERIBERTA CAZARES | F27: KARLA MARQUEZ | J27: FABIAN GONZALEZ QUIROGA
D28: TITULACION | F28: DIRECCION ADMON. Y FINANZAS | J28: DIRECCION GENERAL
J30: FOLIO VOBO
B35: Fecha: | C35: =(CAPTURA!E8) -> 46079 | F35: San Pedro Garza García, Nuevo León
B37: Fraccionamiento: | C37: =(CAPTURA!I17) -> SANTTE RESIDENCIAL | F37: Mza: | G37: =(CAPTURA!I19) -> 45 | H37: Lote: | I37: =(CAPTURA!I20) -> 16 | K37: Int: | L37: =(CAPTURA!I21) -> 114
B39: Comprador: | C39: =CONCATENATE(CAPTURA!E11, " ",CAPTURA!E12, " ", CAPTURA!E13) -> AMIRA IRACEMA TORRES GONZALEZ | H39: M2: | I39: =(CAPTURA!I24) -> 166.929
B41: RFC: | C41: =(CAPTURA!E16) -> TOGA710207HC3
B43: Precio: | C43: =(CAPTURA!I26) -> 2100000 | F43: Precio por M2: $ | I43: =(CAPTURA!I25) -> 12580.199
B45: Exp. Catastral: | C45: =(CAPTURA!I23) -> 0 | F45: Prototipo: | I45: =(CAPTURA!I18) -> TERRENO
B47: Esc. Pública: | F47: Notaria:
B49: Nota:
D56: HERIBERTA CAZARES | F56: KARLA MARQUEZ | J56: FABIAN GONZALEZ QUIROGA
D57: TITULACION | F57: DIRECCION ADMON. Y FINANZAS | J57: DIRECTOR GENERAL

Sheet Oferta de compra_moral
J2: San Pedro Garza García, Nuevo León
J3: Fecha: | K3: =(CAPTURA!E8) -> 46079
J4: Num. Cliente: | K4: =(CAPTURA!E9) -> 0
B7: O F E R TA D E C O M P R A (ALT.001)
B9: O F E R E N T E
B10: Nombre: | C10: =(CAPTURA!E34) -> 0 | H10: RFC: | I10: =(CAPTURA!E35) -> 0
B11: Domicilio - Calle: | C11: =(CAPTURA!E36) -> 0 | H11: Teléfono Oficina: | I11: =(CAPTURA!E42) -> 0
B12: Número Ext. / Int. | C12: =(CAPTURA!E37) -> 0
B13: Colonia: | C13: =(CAPTURA!E38) -> 0
B14: Ciudad/Municipio: | C14: =(CAPTURA!E39) -> 0 | H14: Firma Contrato: | I14: =(CAPTURA!J50) -> 45944
B15: Estado: | C15: =(CAPTURA!E40) -> 0
B17: L O T E
B18: Fraccionamiento: | C18: =(CAPTURA!I17) -> SANTTE RESIDENCIAL | H18: Superficie M2: | I18: =(CAPTURA!I24) -> 166.929
B19: Manzana: | C19: =(CAPTURA!I19) -> 45 | H19: Precio M2: | I19: =(CAPTURA!I25) -> 12580.199 | J19: =(CAPTURA!I25) -> 12580.199
B20: Lote: | C20: =(CAPTURA!I20) -> 16 | H20: Precio: | I20: =(CAPTURA!I26) -> 2100000 | J20: =(CAPTURA!I26) -> 2100000
B21: Número Oficial: | C21: =(CAPTURA!I21) -> 114 | H21: Ptototipo: | I21: =(CAPTURA!I18) -> TERRENO
B22: Calle: | C22: =(CAPTURA!I22) -> AZALEA
B24: F O R M A D E P A G O
B25: Tipo de Crédito: | E25: =(CAPTURA!I28) -> CREDITO DIRECTO
B26: Institución de Crédito: | E26: =(CAPTURA!I29) -> N/A
B28: NUMERO | C28: CONCEPTO | E28: FECHA | F28: CAPITAL | H28: INTERES | I28: PAGO CAPITAL | K28: PAGO TOTAL
B30: =(CAPTURA!H32) -> 1 | C30: =(CAPTURA!I32) -> SEPARACION | E30: =(CAPTURA!J32) -> 14 ENERO 2026 | F30: =(CAPTURA!K32) -> 2100000 | G30: =(CAPTURA!K32) -> 2100000 | H30: =(CAPTURA!L32) -> 0 | I30: =(CAPTURA!M32) -> 50000 | J30: =(CAPTURA!M32) -> 50000 | K30: =(CAPTURA!N32) -> 50000
B31: =(CAPTURA!H33) -> 2 | C31: =(CAPTURA!I33) -> ENGANCHE | E31: =(CAPTURA!J33) -> 26 ENERO 2026 | F31: =(CAPTURA!K33) -> 2050000 | G31: =(CAPTURA!K33) -> 2050000 | H31: =(CAPTURA!L33) -> 0 | I31: =(CAPTURA!M33) -> 630000 | J31: =(CAPTURA!M33) -> 630000 | K31: =(CAPTURA!N33) -> 630000
B32: =(CAPTURA!H34) -> 3 | C32: =(CAPTURA!I34) -> ESCRITURACIÓN | E32: =(CAPTURA!J34) -> 2 MARZO 2026 | F32: =(CAPTURA!K34) -> 1420000 | G32: =(CAPTURA!K34) -> 1420000 | H32: =(CAPTURA!L34) -> 0 | I32: =(CAPTURA!M34) -> 1420000 | J32: =(CAPTURA!M34) -> 1420000 | K32: =(CAPTURA!N34) -> 1420000
B33: =(CAPTURA!H35) -> 0 | C33: =(CAPTURA!I35) -> 0 | E33: =(CAPTURA!J35) -> 0 | F33: =(CAPTURA!K35) -> 0 | G33: =(CAPTURA!K35) -> 0 | H33: =(CAPTURA!L35) -> 0 | I33: =(CAPTURA!M35) -> 0 | J33: =(CAPTURA!M35) -> 0 | K33: =(CAPTURA!N35) -> 0
B34: =(CAPTURA!H36) -> 0 | C34: =(CAPTURA!I36) -> 0 | E34: =(CAPTURA!J36) -> 0 | F34: =(CAPTURA!K36) -> 0 | G34: =(CAPTURA!K36) -> 0 | H34: =(CAPTURA!L36) -> 0 | I34: =(CAPTURA!M36) -> 0 | J34: =(CAPTURA!M36) -> 0 | K34: =(CAPTURA!N36) -> 0
B35: =(CAPTURA!H37) -> 0 | C35: =(CAPTURA!I37) -> 0 | E35: =(CAPTURA!J37) -> 0 | F35: =(CAPTURA!K37) -> 0 | G35: =(CAPTURA!K37) -> 0 | H35: =(CAPTURA!L37) -> 0 | I35: =(CAPTURA!M37) -> 0 | J35: =(CAPTURA!M37) -> 0 | K35: =(CAPTURA!N37) -> 0
B36: =(CAPTURA!H38) -> 0 | C36: =(CAPTURA!I38) -> 0 | E36: =(CAPTURA!J38) -> 0 | F36: =(CAPTURA!K38) -> 0 | G36: =(CAPTURA!K38) -> 0 | H36: =(CAPTURA!L38) -> 0 | I36: =(CAPTURA!M38) -> 0 | J36: =(CAPTURA!M38) -> 0 | K36: =(CAPTURA!N38) -> 0
B37: =(CAPTURA!H39) -> 0 | C37: =(CAPTURA!I39) -> 0 | E37: =(CAPTURA!J39) -> 0 | F37: =(CAPTURA!K39) -> 0 | G37: =(CAPTURA!K39) -> 0 | H37: =(CAPTURA!L39) -> 0 | I37: =(CAPTURA!M39) -> 0 | J37: =(CAPTURA!M39) -> 0 | K37: =(CAPTURA!N39) -> 0
B38: =(CAPTURA!H40) -> 0 | C38: =(CAPTURA!I40) -> 0 | E38: =(CAPTURA!J40) -> 0 | F38: =(CAPTURA!K40) -> 0 | G38: =(CAPTURA!K40) -> 0 | H38: =(CAPTURA!L40) -> 0 | I38: =(CAPTURA!M40) -> 0 | J38: =(CAPTURA!M40) -> 0 | K38: =(CAPTURA!N40) -> 0
B39: =(CAPTURA!H41) -> 0 | C39: =(CAPTURA!I41) -> 0 | E39: =(CAPTURA!J41) -> 0 | F39: =(CAPTURA!K41) -> 0 | G39: =(CAPTURA!K41) -> 0 | H39: =(CAPTURA!L41) -> 0 | I39: =(CAPTURA!M41) -> 0 | J39: =(CAPTURA!M41) -> 0 | K39: =(CAPTURA!N41) -> 0
B40: =(CAPTURA!H42) -> 0 | C40: =(CAPTURA!I42) -> 0 | E40: =(CAPTURA!J42) -> 0 | F40: =(CAPTURA!K42) -> 0 | G40: =(CAPTURA!K42) -> 0 | H40: =(CAPTURA!L42) -> 0 | I40: =(CAPTURA!M42) -> 0 | J40: =(CAPTURA!M42) -> 0 | K40: =(CAPTURA!N42) -> 0
B41: =(CAPTURA!H44) -> 0 | C41: =(CAPTURA!I44) -> 0 | E41: =(CAPTURA!J44) -> 0 | F41: =(CAPTURA!K44) -> 0 | G41: =(CAPTURA!K43) -> 0 | H41: =(CAPTURA!L44) -> 0 | I41: =(CAPTURA!M44) -> 0 | J41: =(CAPTURA!M43) -> 0 | K41: =(CAPTURA!N44) -> 0
B42: =(CAPTURA!H45) -> 0 | C42: =(CAPTURA!I45) -> 0 | E42: =(CAPTURA!J45) -> 0 | F42: =(CAPTURA!K45) -> 0 | G42: =(CAPTURA!K44) -> 0 | H42: =(CAPTURA!L45) -> 0 | I42: =(CAPTURA!M45) -> 0 | J42: =(CAPTURA!M44) -> 0 | K42: =(CAPTURA!N45) -> 0
B43: =(CAPTURA!H46) -> 0 | C43: =(CAPTURA!I46) -> 0 | E43: =(CAPTURA!J46) -> 0 | F43: =(CAPTURA!K46) -> 0 | G43: =(CAPTURA!K45) -> 0 | H43: =(CAPTURA!L46) -> 0 | I43: =(CAPTURA!M46) -> 0 | J43: =(CAPTURA!M45) -> 0 | K43: =(CAPTURA!N46) -> 0
C45: =(CAPTURA!I48) -> VALOR TOTAL: | F45: =(CAPTURA!K48) -> 0 | G45: =(CAPTURA!K48) -> 0 | H45: =(CAPTURA!L48) -> 0 | I45: =(CAPTURA!M48) -> 2100000 | J45: =(CAPTURA!M48) -> 2100000 | K45: =(CAPTURA!N48) -> 2100000
J46: =(CAPTURA!M49) -> 0
B48: DATOS PARA DEPOSITOS | E48: CONDICIONES ESPECIALES
B49: VINTAGO DESARROLLOS, S.A. DE C.V.
B50: BANCO: | C50: AFIRME
...

Sheet Generales_moral
I2: San Pedro Garza García, Nuevo León
I3: Fecha: | J3: =(CAPTURA!E8) -> 46079
I4: Num. Cliente: | J4: =(CAPTURA!E9) -> 0
B7: D A T O S G E N E R A L E S D E L S O L I C I T A N T E (ALT.002)
B9: Nombre: | C9: =(CAPTURA!E34) -> 0 | G9: Teléfono Oficina: | H9: =(CAPTURA!E42) -> 0
B10: Domicilio - Calle: | C10: =(CAPTURA!E36) -> 0
B11: Número Ext. / Int | C11: =(CAPTURA!E37) -> 0
B12: Colonia: | C12: =(CAPTURA!E38) -> 0
B13: Ciudad/Municipio: | C13: =(CAPTURA!E39) -> 0
B14: Estado: | C14: =(CAPTURA!E40) -> 0
B15: Código postal: | C15: =(CAPTURA!E41) -> 0
B16: RFC: | C16: =(CAPTURA!E35) -> 0
B18: L O T E
B19: Fraccionamiento: | C19: =(CAPTURA!I17) -> SANTTE RESIDENCIAL | G19: Superficie M2: | H19: =(CAPTURA!I24) -> 166.929
B20: Manzana: | C20: =(CAPTURA!I19) -> 45 | G20: Precio M2: | H20: =(CAPTURA!I25) -> 12580.199 | I20: =(CAPTURA!I25) -> 12580.199
B21: Lote: | C21: =(CAPTURA!I20) -> 16 | G21: Precio: | H21: =(CAPTURA!I26) -> 2100000 | I21: =(CAPTURA!I26) -> 2100000
B22: Número Oficial: | C22: =(CAPTURA!I21) -> 114 | G22: Exp. Catastral: | H22: =(CAPTURA!I23) -> 0
B23: Calle: | C23: =(CAPTURA!I22) -> AZALEA | G23: Prototipo: | H23: =(CAPTURA!I18) -> TERRENO
B25: R E P R E S E N T A N T E L E G A L
B26: Nombre: | C26: =CONCATENATE(CAPTURA!E44, " ",CAPTURA!E47, " ",CAPTURA!E48) | G26: Teléfono Casa: | H26: =(CAPTURA!E62) -> 0
B27: Domicilio - Calle: | C27: =(CAPTURA!E56) -> 0 | G27: Teléfono Celular: | H27: =(CAPTURA!E63) -> 0
B28: Número Ext. / Int | C28: =(CAPTURA!E57) -> 0 | G28: Teléfono Oficina: | H28: =(CAPTURA!E64) -> 0
B29: Colonia: | C29: =(CAPTURA!E58) -> 0 | G29: E-mail: | H29: =(CAPTURA!E65) -> 0
B30: Ciudad/Municipio: | C30: =(CAPTURA!E59) -> 0
B31: Estado: | C31: =(CAPTURA!E60) -> 0
B32: Código postal: | C32: =(CAPTURA!E61) -> 0
B33: RFC: | C33: =(CAPTURA!E51) -> 0
B34: CURP: | C34: =(CAPTURA!E52) -> 0
B35: Lugar de Nacimiento: | C35: =(CAPTURA!E53) -> 0
B36: Ocupación: | C36: =(CAPTURA!E55) -> 0
B38: O B S E R V A C I O N E S
B58: =CONCATENATE(CAPTURA!E44, " ",CAPTURA!E47, " ",CAPTURA!E48) | I58: =CONCATENATE(CAPTURA!I11, " ",CAPTURA!I12, " ",CAPTURA!I13) -> MARIA ELENA HINOJOSA PLANCARTE
B59: REPRESENTANTE LEGAL | I59: ASESOR

Sheet Vobocontrato_moral
J1: CONTRATO VOBO
B6: Fecha: | C6: =(CAPTURA!E8) -> 46079 | F6: San Pedro Garza García, Nuevo León
B8: Fraccionamiento: | C8: =(CAPTURA!I17) -> SANTTE RESIDENCIAL | F8: Mza: | G8: =(CAPTURA!I19) -> 45 | H8: Lote: | I8: =(CAPTURA!I20) -> 16 | K8: Int: | L8: =(CAPTURA!I21) -> 114
B10: Comprador: | C10: =(CAPTURA!E34) -> 0 | H10: M2: | I10: =(CAPTURA!I24) -> 166.929
B12: RFC: | C12: =(CAPTURA!E35) -> 0
B14: Precio: | C14: =(CAPTURA!I26) -> 2100000 | F14: Precio por M2: $ | I14: =(CAPTURA!I25) -> 12580.199
B16: Exp. Catastral: | C16: =(CAPTURA!I23) -> 0 | F16: Prototipo: | I16: =(CAPTURA!I18) -> TERRENO
B18: Plazo: | C18: CONTADO | F18: Tasa de interés: | I18: =(CAPTURA!I30) -> 0
B20: Nota:
B21: Se procederá a la firma del contrato una vez liquidado el monto del mantenimiento, en caso de cancelación la penalización será por el importe del mantenimiento.
D27: KARLA MARQUEZ | F27: ALEJANDRO REYES TELLEZ | J27: FABIAN GONZALEZ QUIROGA
D28: DIRECCION DE ADMON. Y FINANZAS | F28: VENTAS | J28: DIRECCION GENERAL
J30: CONTRATO VOBO
B35: Fecha: | C35: =(CAPTURA!E8) -> 46079 | F35: San Pedro Garza García, Nuevo León
B37: Fraccionamiento: | C37: =(CAPTURA!I17) -> SANTTE RESIDENCIAL | F37: Mza: | G37: =(CAPTURA!I19) -> 45 | H37: Lote: | I37: =(CAPTURA!I20) -> 16 | K37: Int: | L37: =(CAPTURA!I21) -> 114
B39: Comprador: | C39: =(CAPTURA!E34) -> 0 | H39: M2: | I39: =(CAPTURA!I24) -> 166.929
B41: RFC: | C41: =(CAPTURA!E35) -> 0
B43: Precio: | C43: =(CAPTURA!I26) -> 2100000 | F43: Precio por M2: $ | I43: =(CAPTURA!I25) -> 12580.199
B45: Exp. Catastral: | C45: =(CAPTURA!I23) -> 0 | F45: Prototipo: | I45: =(CAPTURA!I18) -> TERRENO
B47: Plazo: | C47: CONTADO | F47: Tasa de interés: | I47: =(CAPTURA!I30) -> 0
B49: Nota:
B50: Se procederá a la firma del contrato una vez liquidado el monto del mantenimiento, en caso de cancelación la penalización será por el importe del mantenimiento.
D56: KARLA MARQUEZ | F56: ALEJANDRO REYES TELLEZ | J56: FABIAN GONZALEZ QUIROGA
D57: DIRECCION DE ADMON. Y FINANZAS | F57: VENTAS | J57: DIRECCION GENERAL

Sheet VoboFolio_moral
J1: FOLIO VOBO
B6: Fecha: | C6: =(CAPTURA!E8) -> 46079 | F6: San Pedro Garza García, Nuevo León
B8: Fraccionamiento: | C8: =(CAPTURA!I17) -> SANTTE RESIDENCIAL | F8: Mza: | G8: =(CAPTURA!I19) -> 45 | H8: Lote: | I8: =(CAPTURA!I20) -> 16 | K8: Int: | L8: =(CAPTURA!I21) -> 114
B10: Comprador: | C10: =(CAPTURA!E34) -> 0 | H10: M2: | I10: =(CAPTURA!I24) -> 166.929
B12: RFC: | C12: =(CAPTURA!E35) -> 0
B14: Precio: | C14: =(CAPTURA!I26) -> 2100000 | F14: Precio por M2: $ | I14: =(CAPTURA!I25) -> 12580.199
B16: Exp. Catastral: | C16: =(CAPTURA!I23) -> 0 | F16: Prototipo: | I16: =(CAPTURA!I18) -> TERRENO
B18: Esc. Pública: | F18: Notaria:
B20: Nota:
D27: HERIBERTA CAZARES | F27: KARLA MARQUEZ | J27: FABIAN GONZALEZ QUIROGA
D28: TITULACION | F28: DIRECCION ADMON. Y FINANZAS | J28: DIRECCION GENERAL
J30: FOLIO VOBO
B35: Fecha: | C35: =(CAPTURA!E8) -> 46079 | F35: San Pedro Garza García, Nuevo León
B37: Fraccionamiento: | C37: =(CAPTURA!I17) -> SANTTE RESIDENCIAL | F37: Mza: | G37: =(CAPTURA!I19) -> 45 | H37: Lote: | I37: =(CAPTURA!I20) -> 16 | K37: Int: | L37: =(CAPTURA!I21) -> 114
B39: Comprador: | C39: =(CAPTURA!E34) -> 0 | H39: M2: | I39: =(CAPTURA!I24) -> 166.929
B41: RFC: | C41: =(CAPTURA!E35) -> 0
B43: Precio: | C43: =(CAPTURA!I26) -> 2100000 | F43: Precio por M2: $ | I43: =(CAPTURA!I25) -> 12580.199
B45: Exp. Catastral: | C45: =(CAPTURA!I23) -> 0 | F45: Prototipo: | I45: =(CAPTURA!I18) -> TERRENO
B47: Esc. Pública: | F47: Notaria:
B49: Nota:
D56: HERIBERTA CAZARES | F56: KARLA MARQUEZ | J56: FABIAN GONZALEZ QUIROGA
D57: TITULACION | F57: DIRECCION ADMON. Y FINANZAS | J57: DIRECCION GENERAL
